Workbook

Sheet tab 1 BS 2025 vs 2026
A1: Graniti Vicentia, L.L.C.
A2: Parent Company : Graniti Vicentia LLC
A3: Graniti Comparative Balance Sheet
A4: End of Dec 2025
A6: Options: Activity Only
A7: Financial Row | B7: Amount
B8: As of Jan 2025 | C8: As of Feb 2025 | D8: As of Mar 2025 | E8: As of Apr 2025 | F8: As of May 2025 | G8: As of Jun 2025 | H8: As of Jul 2025 | I8: As of Aug 2025 | J8: As of Sep 2025 | K8: As of Oct 2025 | L8: As of Nov 2025 | M8: As of Dec 2025 | X8: Next tab
X9: 46023
A10: ASSETS
A11: Current Assets
A12: Bank
A13: 10110 - GV Truist Bank - 4637 | B13: 0 | C13: 0 | D13: 0 | E13: 0 | F13: 0 | G13: 0 | H13: 13448.91 | I13: 20771.52 | J13: 567606.78 | K13: -7426.01 | L13: 184430.26 | M13: -62150.43 | X13: =_xlfn.XLOOKUP(A13,'tabhg 1a bs 2026'!A:A,'tabhg 1a bs 2026'!B:B,,) -> -62150.43
A14: 21050 - Amex GVLLC | B14: 0 | C14: 0 | D14: 0 | E14: 0 | F14: 0 | G14: 0 | H14: 0 | I14: 0 | J14: -41575 | K14: -139787.67 | L14: -220613.63 | M14: -298052.26 | X14: =_xlfn.XLOOKUP(A14,'tabhg 1a bs 2026'!A:A,'tabhg 1a bs 2026'!B:B,,) -> -325692.32
A15: A10000 - Cash (GV LLC) (New) | X15: =_xlfn.XLOOKUP(A15,'tabhg 1a bs 2026'!A:A,'tabhg 1a bs 2026'!B:B,,) -> 0
A16: A10001 - Petty Cash On Hand (New) | B16: 7986782.4 | C16: 8712214.3 | D16: 11798097 | E16: 13700989 | F16: 17109150 | G16: -6415602.5 | H16: -6415602.5 | I16: -6415602.5 | J16: -6415602.5 | K16: -6415602.5 | L16: -6415602.5 | M16: -6415602.5 | X16: =_xlfn.XLOOKUP(A16,'tabhg 1a bs 2026'!A:A,'tabhg 1a bs 2026'!B:B,,) -> -6415602.5
A17: A10002 - Allegiance Bank Texas-2243 (New) | B17: 0 | C17: 0 | D17: 0 | E17: 0 | F17: 0 | G17: 936.03 | H17: 529.52 | I17: 529.52 | J17: 529.52 | K17: 529.52 | L17: 1029.52 | M17: 1029.52 | X17: =_xlfn.XLOOKUP(A17,'tabhg 1a bs 2026'!A:A,'tabhg 1a bs 2026'!B:B,,) -> 1029.52
A18: A10003 - Truist Bank - 4637 (New) | B18: 0 | C18: 0 | D18: 0 | E18: 0 | F18: 0 | G18: 8099.13 | H18: 14223.64 | I18: 14223.64 | J18: 14223.64 | K18: -46828.34 | L18: -108571.57 | M18: -175916.84 | X18: =_xlfn.XLOOKUP(A18,'tabhg 1a bs 2026'!A:A,'tabhg 1a bs 2026'!B:B,,) -> 3696129.7
A19: A10004 - Truist - Savings - 4645 (New) | B19: 0 | C19: 0 | D19: 0 | E19: 0 | F19: 0 | G19: 1221.56 | H19: 1176.57 | I19: 1176.58 | J19: 1176.59 | K19: 1176.6 | L19: 1176.61 | M19: 1176.62 | X19: =_xlfn.XLOOKUP(A19,'tabhg 1a bs 2026'!A:A,'tabhg 1a bs 2026'!B:B,,) -> 1176.62
A20: A10005 - CC - Clearing Account (New) | B20: 0 | C20: 0 | D20: 0 | E20: 0 | F20: 0 | G20: -4091.4 | H20: -4091.4 | I20: -4091.4 | J20: -4091.4 | K20: -4091.4 | L20: -4091.4 | M20: -4091.4 | X20: =_xlfn.XLOOKUP(A20,'tabhg 1a bs 2026'!A:A,'tabhg 1a bs 2026'!B:B,,) -> -4091.4
A21: A10006 - Undeposited Funds (New) | B21: 0 | C21: 0 | D21: 0 | E21: 0 | F21: 0 | G21: 277725.74 | H21: 277725.74 | I21: 277725.74 | J21: 277725.74 | K21: 277725.74 | L21: 277725.74 | M21: 277725.74 | X21: =_xlfn.XLOOKUP(A21,'tabhg 1a bs 2026'!A:A,'tabhg 1a bs 2026'!B:B,,) -> 277725.74
A22: Total - A10000 - Cash (GV LLC) (New) | B22: =SUM(B16:B21) -> 7986782.4 | C22: =SUM(C16:C21) -> 8712214.3 | D22: =SUM(D16:D21) -> 11798097 | E22: =SUM(E16:E21) -> 13700989 | F22: =SUM(F16:F21) -> 17109150 | G22: =SUM(G16:G21) -> -6131711.4 | H22: =SUM(H16:H21) -> -6126038.4 | I22: =SUM(I16:I21) -> -6126038.4 | ... M22: =SUM(M16:M21) -> -6315678.8 | X22: =_xlfn.XLOOKUP(A22,'tabhg 1a bs 2026'!A:A,'tabhg 1a bs 2026'!B:B,,) -> -2443632.3
A23: Total Bank | B23: =SUM(B13:B14,B22) -> 7986782.4 | C23: =SUM(C13:C14,C22) -> 8712214.3 | D23: =SUM(D13:D14,D22) -> 11798097 | E23: =SUM(E13:E14,E22) -> 13700989 | F23: =SUM(F13:F14,F22) -> 17109150 | G23: =SUM(G13:G14,G22) -> -6131711.4 | H23: =SUM(H13:H14,H22) -> -6112589.5 | I23: =SUM(I13:I14,I22) -> -6105266.9 | ... M23: =SUM(M13:M14,M22) -> -6675881.5 | X23: =_xlfn.XLOOKUP(A23,'tabhg 1a bs 2026'!A:A,'tabhg 1a bs 2026'!B:B,,) -> -2831475
A24: Accounts Receivable | X24: =_xlfn.XLOOKUP(A24,'tabhg 1a bs 2026'!A:A,'tabhg 1a bs 2026'!B:B,,) -> 0
A25: 11000 - Accounts Receivable | B25: 0 | C25: 0 | D25: 0 | E25: 0 | F25: 0 | G25: 33300 | H25: 95758.88 | I25: 225911.11 | J25: 834928.26 | K25: 1049269.3 | L25: 1031006.8 | M25: 993053.75 | X25: =_xlfn.XLOOKUP(A25,'tabhg 1a bs 2026'!A:A,'tabhg 1a bs 2026'!B:B,,) -> 993053.75
A26: A11000 - Accounts Receivable (GV LLC) (New) | X26: =_xlfn.XLOOKUP(A26,'tabhg 1a bs 2026'!A:A,'tabhg 1a bs 2026'!B:B,,) -> 0
A27: A11001 - Accounts Receivable (New) | B27: 6270885.8 | C27: 6270885.8 | D27: 6270885.8 | E27: 6475450.5 | F27: 7013367.4 | G27: 12119591 | H27: 15802724 | I27: 23151709 | J27: 23162048 | K27: 23820658 | L27: 24435725 | M27: 39415246 | X27: =_xlfn.XLOOKUP(A27,'tabhg 1a bs 2026'!A:A,'tabhg 1a bs 2026'!B:B,,) -> 31840880
A28: A11002 - Accrued Accounts Receivable (New) | B28: 0 | C28: 0 | D28: 0 | E28: 0 | F28: 0 | G28: 15430 | H28: 15430 | I28: 15430 | J28: 15430 | K28: 15430 | L28: 15430 | M28: 15430 | X28: =_xlfn.XLOOKUP(A28,'tabhg 1a bs 2026'!A:A,'tabhg 1a bs 2026'!B:B,,) -> 15430
A29: A11003 - Allowance for Doubtful Accounts (New) | B29: 0 | C29: 0 | D29: 0 | E29: 0 | F29: 0 | G29: -766001.85 | H29: -766001.85 | I29: -766001.85 | J29: -766001.85 | K29: -766001.85 | L29: -766001.85 | M29: -766001.85 | X29: =_xlfn.XLOOKUP(A29,'tabhg 1a bs 2026'!A:A,'tabhg 1a bs 2026'!B:B,,) -> -766001.85
A30: Total - A11000 - Accounts Receivable (GV LLC) (New) | B30: =SUM(B27:B29) -> 6270885.8 | C30: =SUM(C27:C29) -> 6270885.8 | D30: =SUM(D27:D29) -> 6270885.8 | E30: =SUM(E27:E29) -> 6475450.5 | F30: =SUM(F27:F29) -> 7013367.4 | G30: =SUM(G27:G29) -> 11369019 | H30: =SUM(H27:H29) -> 15052152 | I30: =SUM(I27:I29) -> 22401137 | ... M30: =SUM(M27:M29) -> 38664674 | X30: =_xlfn.XLOOKUP(A30,'tabhg 1a bs 2026'!A:A,'tabhg 1a bs 2026'!B:B,,) -> 31090308
A31: Total Accounts Receivable | B31: =SUM(B25,B30) -> 6270885.8 | C31: =SUM(C25,C30) -> 6270885.8 | D31: =SUM(D25,D30) -> 6270885.8 | E31: =SUM(E25,E30) -> 6475450.5 | F31: =SUM(F25,F30) -> 7013367.4 | G31: =SUM(G25,G30) -> 11402319 | H31: =SUM(H25,H30) -> 15147911 | I31: =SUM(I25,I30) -> 22627048 | ... M31: =SUM(M25,M30) -> 39657728 | X31: =_xlfn.XLOOKUP(A31,'tabhg 1a bs 2026'!A:A,'tabhg 1a bs 2026'!B:B,,) -> 32083362
A32: Other Current Asset | X32: =_xlfn.XLOOKUP(A32,'tabhg 1a bs 2026'!A:A,'tabhg 1a bs 2026'!B:B,,) -> 0
A33: 12000 - Inventory | B33: 0 | C33: 0 | D33: 0 | E33: 1740 | F33: 1874.58 | G33: 1874.58 | H33: 249003.98 | I33: 9065776.5 | J33: 1375368.4 | K33: 1678708.7 | L33: 2074540.6 | M33: 2077812.9 | X33: =_xlfn.XLOOKUP(A33,'tabhg 1a bs 2026'!A:A,'tabhg 1a bs 2026'!B:B,,) -> 2078728.2
A34: 13000 - Prepaid Expenses | B34: 0 | C34: 0 | D34: 0 | E34: 0 | F34: 0 | G34: 86072.21 | H34: 2802057.2 | I34: 4481870.7 | J34: 6874155.9 | K34: 8820243.6 | L34: 9605309.8 | M34: 12770664 | X34: =_xlfn.XLOOKUP(A34,'tabhg 1a bs 2026'!A:A,'tabhg 1a bs 2026'!B:B,,) -> 14215715
A35: 15000 - Intercompany Receivable | B35: 0 | C35: 0 | D35: 0 | E35: 0 | F35: 0 | G35: 0 | H35: 0 | I35: 0 | J35: 0 | K35: -18301.82 | L35: -168301.82 | M35: -168301.82 | R35: Gap - accounting vs scm | X35: =_xlfn.XLOOKUP(A35,'tabhg 1a bs 2026'!A:A,'tabhg 1a bs 2026'!B:B,,) -> -168301.82
A36: A12000 - Inventory (GV LLC) (New) | H36: =G37-H37 -> 1345584.5 | N36: tab 5 receipts | O36: tab 6 receipts | P36: recalculated balance | T36: recalculated balance | X36: =_xlfn.XLOOKUP(A36,'tabhg 1a bs 2026'!A:A,'tabhg 1a bs 2026'!B:B,,) -> 0
A37: A12001 - Inventory (New) | B37: 0 | C37: 0 | D37: 0 | E37: 0 | F37: 1538.6 | G37: 14946309 | H37: 13600724 | I37: 7127740 | J37: 5912884.6 | K37: 5226855.2 | L37: 5122429.5 | M37: 4389020 | N37: ='tab12July cogs in sps'!H1235 -> 3347689.8 | O37: ='tab 13 aug cogs in sps'!H5577 -> 51431.11 | P37: =SUM(M37:O37) -> 7788140.8 | R37: =P37-T37 -> -1679930.4 | T37: =SUM(U37:X37) -> 9468071.3 | U37: . | V37: =-'tab 3 bal sheetNtsuite Jan 2026'!J10 -> 417768.92 | W37: =-'tab 3 bal sheetNtsuite Jan 2026'!J9 -> -1462939.7 | X37: =_xlfn.XLOOKUP(A37,'tabhg 1a bs 2026'!A:A,'tabhg 1a bs 2026'!B:B,,) -> 10513242
A38: A12002 - Inventory - In Transit (New) | B38: 0 | C38: 0 | D38: 0 | E38: 0 | F38: 0 | G38: 2135520.9 | H38: 2135520.9 | I38: 2135520.9 | J38: 2135520.9 | K38: 2135520.9 | L38: 2135520.9 | M38: 2135520.9 | U38: . | V38: \ | X38: =_xlfn.XLOOKUP(A38,'tabhg 1a bs 2026'!A:A,'tabhg 1a bs 2026'!B:B,,) -> 2135520.9
A39: A12003 - Obsolete Inventory (New) | B39: 0 | C39: 0 | D39: 0 | E39: 0 | F39: 0 | G39: 899003.97 | H39: 899003.97 | I39: 899003.97 | J39: 899003.97 | K39: 899003.97 | L39: 899003.97 | M39: 899003.97 | X39: =_xlfn.XLOOKUP(A39,'tabhg 1a bs 2026'!A:A,'tabhg 1a bs 2026'!B:B,,) -> 899003.97
A40: A12004 - Hotels Projects/ Tub Surrounds For Obsolete Inventory (New) | B40: 0 | C40: 0 | D40: 0 | E40: 0 | F40: 0 | G40: 1456.86 | H40: 1456.86 | I40: 1456.86 | J40: 1456.86 | K40: 1456.86 | L40: 1456.86 | M40: 1456.86 | X40: =_xlfn.XLOOKUP(A40,'tabhg 1a bs 2026'!A:A,'tabhg 1a bs 2026'!B:B,,) -> 1456.86
A41: A12005 - Inventory Adjustments (New) | B41: 0 | C41: 0 | D41: 0 | E41: 0 | F41: 0 | G41: 18722.87 | H41: 18722.87 | I41: 18722.87 | J41: 18722.87 | K41: 18722.87 | L41: 18722.87 | M41: 18722.87 | X41: =_xlfn.XLOOKUP(A41,'tabhg 1a bs 2026'!A:A,'tabhg 1a bs 2026'!B:B,,) -> 18722.87
...

Sheet tabhg 1a bs 2026
A1: Graniti Vicentia, L.L.C.
A2: Parent Company : Graniti Vicentia LLC
A3: Graniti Comparative Balance Sheet
A4: End of Jan 2026
A6: Options: Activity Only
A7: Financial Row | B7: Amount
B8: As of Jan 2026 | C8: As of Feb 2026 | D8: As of Mar 2026 | E8: As of Apr 2026 | F8: As of May 2026 | G8: As of Jun 2026 | H8: As of Jul 2026 | I8: As of Aug 2026 | J8: As of Sep 2026 | K8: As of Oct 2026 | L8: As of Nov 2026 | M8: As of Dec 2026
A10: ASSETS
A11: Current Assets
A12: Bank
A13: 10110 - GV Truist Bank - 4637 | B13: -62150.43 | C13: -62150.43 | D13: -62150.43 | E13: -62150.43 | F13: -62150.43 | G13: -62150.43 | H13: -62150.43 | I13: -62150.43 | J13: -62150.43 | K13: -62150.43 | L13: -62150.43 | M13: -62150.43
A14: 21050 - Amex GVLLC | B14: -325692.32 | C14: -360918.7 | D14: -360918.7 | E14: -360918.7 | F14: -360918.7 | G14: -360918.7 | H14: -360918.7 | I14: -360918.7 | J14: -360918.7 | K14: -360918.7 | L14: -360918.7 | M14: -360918.7
A15: A10000 - Cash (GV LLC) (New)
A16: A10001 - Petty Cash On Hand (New) | B16: -6415602.5 | C16: -6415602.5 | D16: -6415602.5 | E16: -6415602.5 | F16: -6415602.5 | G16: -6415602.5 | H16: -6415602.5 | I16: -6415602.5 | J16: -6415602.5 | K16: -6415602.5 | L16: -6415602.5 | M16: -6415602.5
A17: A10002 - Allegiance Bank Texas-2243 (New) | B17: 1029.52 | C17: 1029.52 | D17: 1029.52 | E17: 1029.52 | F17: 1029.52 | G17: 1029.52 | H17: 1029.52 | I17: 1029.52 | J17: 1029.52 | K17: 1029.52 | L17: 1029.52 | M17: 1029.52
A18: A10003 - Truist Bank - 4637 (New) | B18: 3696129.7 | C18: 3561617.5 | D18: 2965801.7 | E18: 2965801.7 | F18: 2965801.7 | G18: 2965801.7 | H18: 2965801.7 | I18: 2965801.7 | J18: 2965801.7 | K18: 2965801.7 | L18: 2965801.7 | M18: 2965801.7
A19: A10004 - Truist - Savings - 4645 (New) | B19: 1176.62 | C19: 1176.62 | D19: 1176.62 | E19: 1176.62 | F19: 1176.62 | G19: 1176.62 | H19: 1176.62 | I19: 1176.62 | J19: 1176.62 | K19: 1176.62 | L19: 1176.62 | M19: 1176.62
A20: A10005 - CC - Clearing Account (New) | B20: -4091.4 | C20: -4091.4 | D20: -4091.4 | E20: -4091.4 | F20: -4091.4 | G20: -4091.4 | H20: -4091.4 | I20: -4091.4 | J20: -4091.4 | K20: -4091.4 | L20: -4091.4 | M20: -4091.4
A21: A10006 - Undeposited Funds (New) | B21: 277725.74 | C21: 277725.74 | D21: 277725.74 | E21: 277725.74 | F21: 277725.74 | G21: 277725.74 | H21: 277725.74 | I21: 277725.74 | J21: 277725.74 | K21: 277725.74 | L21: 277725.74 | M21: 277725.74
A22: Total - A10000 - Cash (GV LLC) (New) | B22: =SUM(B16:B21) -> -2443632.3 | C22: =SUM(C16:C21) -> -2578144.5 | D22: =SUM(D16:D21) -> -3173960.3 | E22: =SUM(E16:E21) -> -3173960.3 | F22: =SUM(F16:F21) -> -3173960.3 | G22: =SUM(G16:G21) -> -3173960.3 | H22: =SUM(H16:H21) -> -3173960.3 | I22: =SUM(I16:I21) -> -3173960.3 | ... M22: =SUM(M16:M21) -> -3173960.3
A23: Total Bank | B23: =SUM(B13:B14,B22) -> -2831475 | C23: =SUM(C13:C14,C22) -> -3001213.6 | D23: =SUM(D13:D14,D22) -> -3597029.4 | E23: =SUM(E13:E14,E22) -> -3597029.4 | F23: =SUM(F13:F14,F22) -> -3597029.4 | G23: =SUM(G13:G14,G22) -> -3597029.4 | H23: =SUM(H13:H14,H22) -> -3597029.4 | I23: =SUM(I13:I14,I22) -> -3597029.4 | ... M23: =SUM(M13:M14,M22) -> -3597029.4
A24: Accounts Receivable
A25: 11000 - Accounts Receivable | B25: 993053.75 | C25: 952000.45 | D25: 952000.45 | E25: 952000.45 | F25: 952000.45 | G25: 952000.45 | H25: 952000.45 | I25: 952000.45 | J25: 952000.45 | K25: 952000.45 | L25: 952000.45 | M25: 952000.45
A26: A11000 - Accounts Receivable (GV LLC) (New)
A27: A11001 - Accounts Receivable (New) | B27: 31840880 | C27: 29681629 | D27: 26763851 | E27: 26763851 | F27: 26763851 | G27: 26763851 | H27: 26763851 | I27: 26763851 | J27: 26763851 | K27: 26763851 | L27: 26763851 | M27: 26763851
A28: A11002 - Accrued Accounts Receivable (New) | B28: 15430 | C28: 15430 | D28: 15430 | E28: 15430 | F28: 15430 | G28: 15430 | H28: 15430 | I28: 15430 | J28: 15430 | K28: 15430 | L28: 15430 | M28: 15430
A29: A11003 - Allowance for Doubtful Accounts (New) | B29: -766001.85 | C29: -766001.85 | D29: -766001.85 | E29: -766001.85 | F29: -766001.85 | G29: -766001.85 | H29: -766001.85 | I29: -766001.85 | J29: -766001.85 | K29: -766001.85 | L29: -766001.85 | M29: -766001.85
A30: Total - A11000 - Accounts Receivable (GV LLC) (New) | B30: =SUM(B27:B29) -> 31090308 | C30: =SUM(C27:C29) -> 28931058 | D30: =SUM(D27:D29) -> 26013279 | E30: =SUM(E27:E29) -> 26013279 | F30: =SUM(F27:F29) -> 26013279 | G30: =SUM(G27:G29) -> 26013279 | H30: =SUM(H27:H29) -> 26013279 | I30: =SUM(I27:I29) -> 26013279 | ... M30: =SUM(M27:M29) -> 26013279
A31: Total Accounts Receivable | B31: =SUM(B25,B30) -> 32083362 | C31: =SUM(C25,C30) -> 29883058 | D31: =SUM(D25,D30) -> 26965280 | E31: =SUM(E25,E30) -> 26965280 | F31: =SUM(F25,F30) -> 26965280 | G31: =SUM(G25,G30) -> 26965280 | H31: =SUM(H25,H30) -> 26965280 | I31: =SUM(I25,I30) -> 26965280 | ... M31: =SUM(M25,M30) -> 26965280
A32: Other Current Asset
A33: 10200 - Undeposited Funds | B33: 817418.46 | C33: 817418.46 | D33: 833224.26 | E33: 833224.26 | F33: 833224.26 | G33: 833224.26 | H33: 833224.26 | I33: 833224.26 | J33: 833224.26 | K33: 833224.26 | L33: 833224.26 | M33: 833224.26
A34: 12000 - Inventory | B34: 2078728.2 | C34: 2085538.6 | D34: 2085557.8 | E34: 2085557.8 | F34: 2085557.8 | G34: 2085557.8 | H34: 2085557.8 | I34: 2085557.8 | J34: 2085557.8 | K34: 2085557.8 | L34: 2085557.8 | M34: 2085557.8
A35: 13000 - Prepaid Expenses | B35: 14215715 | C35: 12755063 | D35: 10050416 | E35: 10050416 | F35: 10050416 | G35: 10050416 | H35: 10050416 | I35: 10050416 | J35: 10050416 | K35: 10050416 | L35: 10050416 | M35: 10050416
A36: 15000 - Intercompany Receivable | B36: -168301.82 | C36: -168301.82 | D36: -168301.82 | E36: -168301.82 | F36: -168301.82 | G36: -168301.82 | H36: -168301.82 | I36: -168301.82 | J36: -168301.82 | K36: -168301.82 | L36: -168301.82 | M36: -168301.82
A37: A12000 - Inventory (GV LLC) (New)
A38: A12001 - Inventory (New) | B38: 10513242 | C38: 11225865 | D38: 11904841 | E38: 11904841 | F38: 11904841 | G38: 11904841 | H38: 11904841 | I38: 11904841 | J38: 11904841 | K38: 11904841 | L38: 11904841 | M38: 11904841
A39: A12002 - Inventory - In Transit (New) | B39: 2135520.9 | C39: 2135520.9 | D39: 2135520.9 | E39: 2135520.9 | F39: 2135520.9 | G39: 2135520.9 | H39: 2135520.9 | I39: 2135520.9 | J39: 2135520.9 | K39: 2135520.9 | L39: 2135520.9 | M39: 2135520.9
A40: A12003 - Obsolete Inventory (New) | B40: 899003.97 | C40: 899003.97 | D40: 899003.97 | E40: 899003.97 | F40: 899003.97 | G40: 899003.97 | H40: 899003.97 | I40: 899003.97 | J40: 899003.97 | K40: 899003.97 | L40: 899003.97 | M40: 899003.97
A41: A12004 - Hotels Projects/ Tub Surrounds For Obsolete Inventory (New) | B41: 1456.86 | C41: 1456.86 | D41: 1456.86 | E41: 1456.86 | F41: 1456.86 | G41: 1456.86 | H41: 1456.86 | I41: 1456.86 | J41: 1456.86 | K41: 1456.86 | L41: 1456.86 | M41: 1456.86
A42: A12005 - Inventory Adjustments (New) | B42: 18722.87 | C42: 18722.87 | D42: 18722.87 | E42: 18722.87 | F42: 18722.87 | G42: 18722.87 | H42: 18722.87 | I42: 18722.87 | J42: 18722.87 | K42: 18722.87 | L42: 18722.87 | M42: 18722.87
...

Sheet tab 2 IS 2025
A1: Graniti Vicentia, L.L.C.
A2: Parent Company : Graniti Vicentia LLC
A3: Graniti Comparative Income Statement
A4: From Jan 2025 to Dec 2025
A6: Options: Activity Only
A7: Financial Row | B7: Amount
B8: Jan 2025 | C8: Feb 2025 | D8: Mar 2025 | E8: Apr 2025 | F8: May 2025 | G8: Jun 2025 | H8: Jul 2025 | I8: Aug 2025 | J8: Sep 2025 | K8: Oct 2025 | L8: Nov 2025 | M8: Dec 2025
A10: Ordinary Income/Expense
A11: Income
A12: 40000 - Revenue
A13: 40100 - Sales Revenue | B13: 0 | C13: 0 | D13: 0 | E13: 0 | F13: 0 | G13: 0 | H13: 0 | I13: 0 | J13: 30000 | K13: 0 | L13: 130964.94 | M13: 241290.64
A14: 40400 - Sales Discount (SALE) | B14: 0 | C14: 0 | D14: 0 | E14: 0 | F14: 0 | G14: 0 | H14: -435.68 | I14: -2765.45 | J14: -33.92 | K14: -54691.8 | L14: -11130.95 | M14: -117510.55
A15: Total - 40000 - Revenue | B15: =SUM(B13:B14) -> 0 | C15: =SUM(C13:C14) -> 0 | D15: =SUM(D13:D14) -> 0 | E15: =SUM(E13:E14) -> 0 | F15: =SUM(F13:F14) -> 0 | G15: =SUM(G13:G14) -> 0 | H15: =SUM(H13:H14) -> -435.68 | I15: =SUM(I13:I14) -> -2765.45 | ... M15: =SUM(M13:M14) -> 123780.09
A16: A40000 - Revenue (GV LLC) (New)
A17: A40001 - Sales Income (New) | B17: 0 | C17: 0 | D17: 0 | E17: -650707.54 | F17: 0 | G17: 32945684 | H17: 3387410.1 | I17: 5935080 | J17: 372145.86 | K17: 738740.19 | L17: 879104.09 | M17: 12848564
A18: A40004 - Other Income (New) | B18: 0 | C18: 0 | D18: 0 | E18: 0 | F18: 0 | G18: 0 | H18: 0 | I18: 0 | J18: 97947 | K18: 0 | L18: 0 | M18: 0
A19: A40005 - Sales Discount (SALE) (New) | B19: 0 | C19: 0 | D19: 0 | E19: 0 | F19: 0 | G19: -1428154 | H19: 0 | I19: 0 | J19: -97947 | K19: 0 | L19: 0 | M19: 0
A20: A40006 - Delivery Income (New) | B20: 0 | C20: 0 | D20: 0 | E20: 0 | F20: 0 | G20: 5258318.7 | H20: 186080.66 | I20: 1070510.5 | J20: 232169.18 | K20: 294170.78 | L20: 731766.18 | M20: 1819403
A21: A40007 - Service Income (New) | B21: 0 | C21: 0 | D21: 0 | E21: 0 | F21: 0 | G21: 1403377.5 | H21: 135165.82 | I21: 295927.18 | J21: 0 | K21: 0 | L21: 0 | M21: 0
A22: Total - A40000 - Revenue (GV LLC) (New) | B22: =SUM(B17:B21) -> 0 | C22: =SUM(C17:C21) -> 0 | D22: =SUM(D17:D21) -> 0 | E22: =SUM(E17:E21) -> -650707.54 | F22: =SUM(F17:F21) -> 0 | G22: =SUM(G17:G21) -> 38179226 | H22: =SUM(H17:H21) -> 3708656.6 | I22: =SUM(I17:I21) -> 7301517.6 | ... M22: =SUM(M17:M21) -> 14667967
A23: Total - Income | B23: =SUM(B15,B22) -> 0 | C23: =SUM(C15,C22) -> 0 | D23: =SUM(D15,D22) -> 0 | E23: =SUM(E15,E22) -> -650707.54 | F23: =SUM(F15,F22) -> 0 | G23: =SUM(G15,G22) -> 38179226 | H23: =SUM(H15,H22) -> 3708220.9 | I23: =SUM(I15,I22) -> 7298752.2 | ... M23: =SUM(M15,M22) -> 14791747
A24: Cost Of Sales
A25: 50000 - Cost of Good Sold
A26: 50000 - Cost of Good Sold | B26: 0 | C26: 0 | D26: 0 | E26: 0 | F26: 0 | G26: 0 | H26: 0 | I26: 0 | J26: 1284309 | K26: 0 | L26: 0 | M26: -137547.52
A27: 50040 - Freight & Delivery Charges | B27: 31042 | C27: 3225 | D27: 66695.8 | E27: 280094.32 | F27: 226202.12 | G27: 315360.35 | H27: 571461.32 | I27: 492205.31 | J27: 454666.67 | K27: 294479.34 | L27: 213661.21 | M27: -128401.58
A28: 50050 - Contract Labor | B28: 0 | C28: 0 | D28: 0 | E28: 0 | F28: 0 | G28: 26568.29 | H28: 360170.13 | I28: 322244.44 | J28: 219600.96 | K28: 134126.79 | L28: 2916.67 | M28: 2916.67
A29: 50070 - Small Tools & Equipment | B29: 0 | C29: 0 | D29: 30 | E29: 1431.34 | F29: 1528.1 | G29: 3476.43 | H29: 17558.88 | I29: 10353.51 | J29: 2184.36 | K29: 7430.34 | L29: 4820.81 | M29: 104.17
A30: 50090 - Design Services | B30: 0 | C30: 0 | D30: 0 | E30: 0 | F30: 10000 | G30: 100000 | H30: 108072.33 | I30: 8241.4 | J30: 0 | K30: 100000 | L30: 0 | M30: 100000
A31: 50100 - Fabrication Expense | B31: 0 | C31: 0 | D31: 0 | E31: 25574.4 | F31: 5916 | G31: 3013 | H31: 24332.54 | I31: 50549.58 | J31: 51301.91 | K31: 26369.76 | L31: 14498.83 | M31: 948
A32: 50200 - Materials and Product Expense | B32: 0 | C32: 0 | D32: 0 | E32: 0 | F32: 19517.49 | G32: 15516.92 | H32: 110384.43 | I32: -8355883.9 | J32: 8149361 | K32: 325115.07 | L32: 463160.78 | M32: 91942.45
A33: Total - 50000 - Cost of Good Sold | B33: =SUM(B26:B32) -> 31042 | C33: =SUM(C26:C32) -> 3225 | D33: =SUM(D26:D32) -> 66725.8 | E33: =SUM(E26:E32) -> 307100.06 | F33: =SUM(F26:F32) -> 263163.71 | G33: =SUM(G26:G32) -> 463934.99 | H33: =SUM(H26:H32) -> 1191979.6 | I33: =SUM(I26:I32) -> -7472289.6 | ... M33: =SUM(M26:M32) -> -70037.81
A34: A50000 - Cost of Goods Sales 50 (GV LLC) (New) | H34: tab 5 issues
A35: A50001 - Cost Of Goods Sold (New) | B35: 170376.66 | C35: 225150.26 | D35: -12170.1 | E35: 369243.21 | F35: -808653.14 | G35: 27272255 | H35: 2639865.6 | I35: 6944149.4 | J35: -38450.35 | K35: 1013484.3 | L35: 1512264.4 | M35: 4003391.8
A36: A50002 - Other Purchase Charges (New) | B36: 0 | C36: 0 | D36: 0 | E36: 0 | F36: 0 | G36: 3451.47 | H36: 0 | I36: 0 | J36: 0 | K36: 0 | L36: 0 | M36: 0
A37: A50003 - Customs Clearance (New) | B37: 0 | C37: 0 | D37: 0 | E37: 0 | F37: 0 | G37: 186947.96 | H37: -85051.09 | I37: -86444.78 | J37: 0 | K37: 0 | L37: 0 | M37: 0
A38: A50004 - Other Expense (New) | B38: 0 | C38: 0 | D38: 0 | E38: 0 | F38: 1310.29 | G38: 3826.07 | H38: 6939.02 | I38: 3886.71 | J38: 10300.26 | K38: 11659.48 | L38: 10551.89 | M38: 41764.23
A39: Total - A50000 - Cost of Goods Sales 50 (GV LLC) (New) | B39: =SUM(B35:B38) -> 170376.66 | C39: =SUM(C35:C38) -> 225150.26 | D39: =SUM(D35:D38) -> -12170.1 | E39: =SUM(E35:E38) -> 369243.21 | F39: =SUM(F35:F38) -> -807342.85 | G39: =SUM(G35:G38) -> 27466480 | H39: =SUM(H35:H38) -> 2561753.5 | I39: =SUM(I35:I38) -> 6861591.3 | ... M39: =SUM(M35:M38) -> 4045156
A40: A51000 - Cost of Goods Sales 51 (GV LLC) (New)
A41: A51001 - Freight - Out - Expense (New) | B41: 114507.14 | C41: 39463.76 | D41: 70790.84 | E41: 4742.44 | F41: 38742.89 | G41: 1371255.8 | H41: 190640.5 | I41: 937382.8 | J41: 112752.04 | K41: 236826.13 | L41: 563149.25 | M41: 772626.89
A42: A51002 - Freight - Inn - Expenses (New) | B42: 0 | C42: 0 | D42: 0 | E42: 0 | F42: 0 | G42: 76774.35 | H42: -76774.35 | I42: 0 | J42: 247.5 | K42: 488.42 | L42: 9478.57 | M42: 86840.24
...

Sheet tab 3 bal sheetNtsuite Jan 2026
A1: Graniti Vicentia, L.L.C.
A2: Parent Company : Graniti Vicentia LLC
A3: Balance Sheet Detail
A4: Jan 2026
A7: Financial Row | B7: Type | C7: Date | D7: Document Number | E7: Name | F7: Amount | G7: Balance | I7: {=_xlfn.UNIQUE(B:B)} -> 0
A8: ASSETS | F8: 0 | G8: 0 | I8: Type
A9: Current Assets | F9: 0 | G9: 0 | I9: Item Receipt | J9: =SUMIF(B:B,I9,F:F) -> 1462939.7
A10: Other Current Asset | F10: 0 | G10: 0 | I10: Item Fulfillment | J10: =SUMIF(B:B,I10,F:F) -> -417768.92
A11: A12000 - Inventory (GV LLC) (New) | F11: 0 | G11: 0 | I11: Inventory Adjustment | J11: =SUMIF(B:B,I11,F:F) -> 5079051.3
A12: A12001 - Inventory (New) | F12: 0 | G12: 4389020
B13: Item Receipt | C13: 46023 | D13: IR1444 | E13: U.S. Vinyl Manufacturing Corp | F13: 342.6 | G13: =G12+F13 -> 4389362.6 | I13: Net
B14: Item Receipt | C14: 46023 | D14: IR1444 | E14: U.S. Vinyl Manufacturing Corp | F14: 477.5 | G14: =G13+F14 -> 4389840.1
B15: Item Receipt | C15: 46023 | D15: IR1444 | F15: -342.6 | G15: =G14+F15 -> 4389497.5
B16: Item Receipt | C16: 46023 | D16: IR1444 | F16: -477.5 | G16: =G15+F16 -> 4389020
B17: Item Receipt | C17: 46024 | D17: IR939 | E17: MirageGranitoCeramico S.p.A | F17: 23358.03 | G17: =G16+F17 -> 4412378
B18: Item Receipt | C18: 46024 | D18: IR940 | E18: MirageGranitoCeramico S.p.A | F18: 683.55 | G18: =G17+F18 -> 4413061.5
B19: Item Receipt | C19: 46024 | D19: IR941 | E19: HARMONY HOSPITALITY CO LTD | F19: 345.23 | G19: =G18+F19 -> 4413406.8
B20: Item Receipt | C20: 46024 | D20: IR942 | E20: HARMONY HOSPITALITY CO LTD | F20: 207.73 | G20: =G19+F20 -> 4413614.5
B21: Item Receipt | C21: 46024 | D21: IR943 | E21: HARMONY HOSPITALITY CO LTD | F21: 742.43 | G21: =G20+F21 -> 4414356.9
B22: Item Receipt | C22: 46024 | D22: IR944 | E22: HARMONY HOSPITALITY CO LTD | F22: 386.01 | G22: =G21+F22 -> 4414742.9
B23: Item Receipt | C23: 46024 | D23: IR945 | E23: HARMONY HOSPITALITY CO LTD | F23: 882 | G23: =G22+F23 -> 4415624.9
B24: Item Receipt | C24: 46024 | D24: IR945 | F24: -882 | G24: =G23+F24 -> 4414742.9
B25: Item Receipt | C25: 46024 | D25: IR946 | E25: HARMONY HOSPITALITY CO LTD | F25: 87.75 | G25: =G24+F25 -> 4414830.7
B26: Item Receipt | C26: 46024 | D26: IR946 | F26: -87.75 | G26: =G25+F26 -> 4414742.9
B27: Item Receipt | C27: 46024 | D27: IR947 | E27: HARMONY HOSPITALITY CO LTD | F27: 126.5 | G27: =G26+F27 -> 4414869.4
B28: Item Receipt | C28: 46024 | D28: IR947 | F28: -28.09 | G28: =G27+F28 -> 4414841.4
B29: Item Receipt | C29: 46024 | D29: IR948 | E29: HARMONY HOSPITALITY CO LTD | F29: 2264 | G29: =G28+F29 -> 4417105.4
B30: Item Receipt | C30: 46024 | D30: IR948 | F30: -2264 | G30: =G29+F30 -> 4414841.4
B31: Item Receipt | C31: 46024 | D31: IR949 | E31: HARMONY HOSPITALITY CO LTD | F31: 176 | G31: =G30+F31 -> 4415017.4
B32: Item Receipt | C32: 46024 | D32: IR949 | F32: -176 | G32: =G31+F32 -> 4414841.4
B33: Item Receipt | C33: 46024 | D33: IR950 | E33: HARMONY HOSPITALITY CO LTD | F33: 3144 | G33: =G32+F33 -> 4417985.4
B34: Item Receipt | C34: 46024 | D34: IR951 | E34: HARMONY HOSPITALITY CO LTD | F34: 320 | G34: =G33+F34 -> 4418305.4
B35: Item Receipt | C35: 46024 | D35: IR952 | E35: HARMONY HOSPITALITY CO LTD | F35: 2134.59 | G35: =G34+F35 -> 4420439.9
B36: Item Receipt | C36: 46024 | D36: IR952 | F36: -2134.59 | G36: =G35+F36 -> 4418305.4
B37: Item Receipt | C37: 46024 | D37: IR953 | E37: HARMONY HOSPITALITY CO LTD | F37: 3140.2 | G37: =G36+F37 -> 4421445.6
B38: Item Receipt | C38: 46024 | D38: IR954 | E38: HARMONY HOSPITALITY CO LTD | F38: 1677.8 | G38: =G37+F38 -> 4423123.4
B39: Item Receipt | C39: 46024 | D39: IR954 | F39: -1677.8 | G39: =G38+F39 -> 4421445.6
B40: Item Receipt | C40: 46024 | D40: IR955 | E40: HARMONY HOSPITALITY CO LTD | F40: 1528 | G40: =G39+F40 -> 4422973.6
B41: Item Receipt | C41: 46024 | D41: IR955 | F41: -1528 | G41: =G40+F41 -> 4421445.6
B42: Item Receipt | C42: 46024 | D42: IR956 | E42: HARMONY HOSPITALITY CO LTD | F42: 2060 | G42: =G41+F42 -> 4423505.6
...

Sheet tab 4 Nsuite July Income statem
A1: Graniti Vicentia, L.L.C.
A2: Parent Company : Graniti Vicentia LLC
A3: Graniti - Income Statement Detail
A4: Jul 2025
A6: Options: Activity Only
A7: Financial Row | B7: Type | C7: Date | D7: Document Number | E7: Name | F7: Entity (Line) | G7: Clr | H7: Split | I7: Reference No. | J7: Description | K7: Memo | L7: Amount
A8: Ordinary Income/Expense
A9: Cost Of Sales
A10: A50000 - Cost of Goods Sales 50 (GV LLC) (New) | N10: 0
A11: A50001 - Cost Of Goods Sold (New) | N11: Type
B12: Journal | C12: 45839 | D12: JE1831 | F12: LaQuinta - Naples - FL - Raj Mukkirla | G12: F | H12: A12001 - Inventory (GV LLC) (New) : Inventory (New) | I12: 34076 | J12: LaQuinta - Naples - FL - Raj MukkirlaImport July 25 cogs for materials from SPS to Netsuite | K12: LaQuinta - Naples - FL - Raj MukkirlaImport July 25 cogs for materials from SPS to Netsuite | L12: 6083.65 | N12: Journal | O12: =SUMIF(B:B,N12,L:L) -> 2619838.7
B13: Journal | C13: 45839 | D13: JE1011 | F13: Monsoon Flower LLC | G13: F | H13: A12001 - Inventory (GV LLC) (New) : Inventory (New) | I13: 37959/2 | J13: Monsoon Flower LLCImport July 25 cogs for materials from SPS to Netsuite | K13: Monsoon Flower LLCImport July 25 cogs for materials from SPS to Netsuite | L13: 12463.65 | N13: Bill | O13: =SUMIF(B:B,N13,L:L) -> 18605.75
B14: Journal | C14: 45839 | D14: JE1007 | F14: Graniti Vicentia | G14: F | H14: A12001 - Inventory (GV LLC) (New) : Inventory (New) | I14: 36159/4 | J14: Graniti VicentiaImport July 25 cogs for materials from SPS to Netsuite | K14: Graniti VicentiaImport July 25 cogs for materials from SPS to Netsuite | L14: 2609.63 | N14: Item Receipt | O14: =SUMIF(B:B,N14,L:L) -> 1421.14
B15: Journal | C15: 45839 | D15: JE1001 | F15: Magnolia LXR Dallas TX - | G15: F | H15: A12001 - Inventory (GV LLC) (New) : Inventory (New) | I15: 34086/8 | J15: Magnolia LXR Dallas TX -Import July 25 cogs for materials from SPS to Netsuite | K15: Magnolia LXR Dallas TX -Import July 25 cogs for materials from SPS to Netsuite | L15: 10311.03
B16: Journal | C16: 45839 | D16: JE1000 | F16: LaQuinta/Hawthone - Knoxville TN - AMit | G16: F | H16: A12001 - Inventory (GV LLC) (New) : Inventory (New) | I16: 33722/5 | J16: LaQuinta/Hawthone - Knoxville TN - AMitImport July 25 cogs for materials from SPS to Netsuite | K16: LaQuinta/Hawthone - Knoxville TN - AMitImport July 25 cogs for materials from SPS to Netsuite | L16: 848
B17: Journal | C17: 45839 | D17: JE1008 | F17: CANDLEWOOD EASTRIDGE TN | G17: F | H17: A12001 - Inventory (GV LLC) (New) : Inventory (New) | I17: 36221 | J17: CANDLEWOOD EASTRIDGE TNImport July 25 cogs for materials from SPS to Netsuite | K17: CANDLEWOOD EASTRIDGE TNImport July 25 cogs for materials from SPS to Netsuite | L17: 386.87
B18: Journal | C18: 45839 | D18: JE999 | F18: La Quinta Orlando | G18: F | H18: A12001 - Inventory (GV LLC) (New) : Inventory (New) | I18: 33565/10 | J18: LA QUINTA ORLANDOImport July 25 cogs for materials from SPS to Netsuite | K18: LA QUINTA ORLANDOImport July 25 cogs for materials from SPS to Netsuite | L18: 893.18
B19: Journal | C19: 45839 | D19: JE998 | F19: Magnolia LXR Dallas TX - | G19: F | H19: A12001 - Inventory (GV LLC) (New) : Inventory (New) | I19: 33495/7 | J19: Magnolia LXR Dallas TX -Import July 25 cogs for materials from SPS to Netsuite | K19: Magnolia LXR Dallas TX -Import July 25 cogs for materials from SPS to Netsuite | L19: 3554.96
B20: Journal | C20: 45839 | D20: JE1002 | F20: La Quinta, Anaheim CA | G20: F | H20: A12001 - Inventory (GV LLC) (New) : Inventory (New) | I20: 34113/2 | J20: La Quinta, Anaheim CAImport July 25 cogs for materials from SPS to Netsuite | K20: La Quinta, Anaheim CAImport July 25 cogs for materials from SPS to Netsuite | L20: 980.95
B21: Journal | C21: 45839 | D21: JE1823 | F21: La Quinta Inn & Suites - Seatac Airport - Seattle WA | G21: F | H21: A12001 - Inventory (GV LLC) (New) : Inventory (New) | I21: 33555 | J21: La Quinta Inn & Suites- Seatac Airport- Seattle WAImport July 25 cogs for materials from SPS to Netsuite | K21: La Quinta Inn & Suites- Seatac Airport- Seattle WAImport July 25 cogs for materials from SPS to Netsuite | L21: 10748.91
B22: Journal | C22: 45839 | D22: JE1830 | F22: CANDLEWOOD LAFAYETTE | G22: F | H22: A12001 - Inventory (GV LLC) (New) : Inventory (New) | I22: 33984 | J22: CANDLEWOOD LAFAYETTEImport July 25 cogs for materials from SPS to Netsuite | K22: CANDLEWOOD LAFAYETTEImport July 25 cogs for materials from SPS to Netsuite | L22: 345
B23: Journal | C23: 45839 | D23: JE1006 | F23: Graniti Vicentia | G23: F | H23: A12001 - Inventory (GV LLC) (New) : Inventory (New) | I23: 36158 | J23: Graniti VicentiaImport July 25 cogs for materials from SPS to Netsuite | K23: Graniti VicentiaImport July 25 cogs for materials from SPS to Netsuite | L23: 1277.06
B24: Journal | C24: 45839 | D24: JE995 | F24: Magnolia LXR Dallas TX - | G24: F | H24: A12001 - Inventory (GV LLC) (New) : Inventory (New) | I24: 31647 | J24: Import July 25 cogs for materials from SPS to Netsuite | K24: Import July 25 cogs for materials from SPS to Netsuite | L24: 78.61
B25: Journal | C25: 45839 | D25: JE1003 | F25: LaQuinta Yakima WA | G25: F | H25: A12001 - Inventory (GV LLC) (New) : Inventory (New) | I25: 34289/3 | J25: LaQuinta Yakima WAImport July 25 cogs for materials from SPS to Netsuite | K25: LaQuinta Yakima WAImport July 25 cogs for materials from SPS to Netsuite | L25: 541.7
B26: Journal | C26: 45839 | D26: JE1010 | F26: ELEMENT FORTSMITH, ARKANSAS | G26: F | H26: A12001 - Inventory (GV LLC) (New) : Inventory (New) | I26: 37759/3 | J26: ELEMENT FORTSMITH, ARKANSASImport July 25 cogs for materials from SPS to Netsuite | K26: ELEMENT FORTSMITH, ARKANSASImport July 25 cogs for materials from SPS to Netsuite | L26: 8127.55
... B31: Journal | C31: 45839 | D31: JE1004 | F31: LaQuinta Inn & Suites Oxford AL | G31: F | H31: A12001 - Inventory (GV LLC) (New) : Inventory (New) | I31: 34967 | J31: LaQuinta Inn & Suites Oxford ALImport July 25 cogs for materials from SPS to Netsuite | K31: LaQuinta Inn & Suites Oxford ALImport July 25 cogs for materials from SPS to Netsuite | L31: 3300.55
B32: Bill | C32: 45842 | D32: 45812//SR173-5TPM// CAXU9054830 | E32: Richwood Hospitality Co. LTD | F32: - No Entity - | G32: F | H32: 20000 - Accounts Payable | J32: LM-MW-7T.C Quartz Top @ Restore Cabinet | K32: CAXU9054830 | L32: 240.9
B33: Bill | C33: 45842 | D33: 45812//SR173-5TPM// CAXU9054830 | E33: Richwood Hospitality Co. LTD | F33: - No Entity - | G33: F | H33: 20000 - Accounts Payable | J33: LM-MW-9.3.C Quartz Top @ Bar Back Wall Cabinet | K33: CAXU9054830 | L33: 1391.5
B34: Journal | C34: 45845 | D34: JE1019 | F34: Auburn Hospitality Group | G34: F | H34: A12001 - Inventory (GV LLC) (New) : Inventory (New) | I34: 38382/3 | J34: Auburn Hospitality GroupImport July 25 cogs for materials from SPS to Netsuite | K34: Auburn Hospitality GroupImport July 25 cogs for materials from SPS to Netsuite | L34: 207.44
B35: Journal | C35: 45845 | D35: JE1017 | F35: Fairfield Townplace East Hartford | G35: F | H35: A12001 - Inventory (GV LLC) (New) : Inventory (New) | I35: 37579/2 | J35: Fairfield Townplace East HartfordImport July 25 cogs for materials from SPS to Netsuite | K35: Fairfield Townplace East HartfordImport July 25 cogs for materials from SPS to Netsuite | L35: 358.55
B36: Journal | C36: 45845 | D36: JE1016 | F36: Fairfield Townplace East Hartford | G36: F | H36: A12001 - Inventory (GV LLC) (New) : Inventory (New) | I36: 35812 | J36: Fairfield Townplace East HartfordImport July 25 cogs for materials from SPS to Netsuite | K36: Fairfield Townplace East HartfordImport July 25 cogs for materials from SPS to Netsuite | L36: 27258.19
B37: Journal | C37: 45845 | D37: JE1015 | F37: Fairfield Townplace East Hartford | G37: F | H37: A12001 - Inventory (GV LLC) (New) : Inventory (New) | I37: 35808 | J37: Fairfield Townplace East HartfordImport July 25 cogs for materials from SPS to Netsuite | K37: Fairfield Townplace East HartfordImport July 25 cogs for materials from SPS to Netsuite | L37: 7421.01
B38: Journal | C38: 45845 | D38: JE1021 | F38: Auburn Hospitality Group | G38: F | H38: A12001 - Inventory (GV LLC) (New) : Inventory (New) | I38: 38403/3 | J38: Auburn Hospitality GroupImport July 25 cogs for materials from SPS to Netsuite | K38: Auburn Hospitality GroupImport July 25 cogs for materials from SPS to Netsuite | L38: 518.72
B39: Journal | C39: 45845 | D39: JE1023 | F39: Auburn Hospitality Group | G39: F | H39: A12001 - Inventory (GV LLC) (New) : Inventory (New) | I39: 38738 | J39: Auburn Hospitality GroupImport July 25 cogs for materials from SPS to Netsuite | K39: Auburn Hospitality GroupImport July 25 cogs for materials from SPS to Netsuite | L39: 527.46
B40: Journal | C40: 45845 | D40: JE1018 | F40: Hampton Inn Nashville | G40: F | H40: A12001 - Inventory (GV LLC) (New) : Inventory (New) | I40: 38235/4 | J40: Hampton Inn NashvilleImport July 25 cogs for materials from SPS to Netsuite | K40: Hampton Inn NashvilleImport July 25 cogs for materials from SPS to Netsuite | L40: 6139.05
B41: Journal | C41: 45845 | D41: JE1014 | F41: Fairfield Townplace East Hartford | G41: F | H41: A12001 - Inventory (GV LLC) (New) : Inventory (New) | I41: 35807 | J41: Fairfield Townplace East HartfordImport July 25 cogs for materials from SPS to Netsuite | K41: Fairfield Townplace East HartfordImport July 25 cogs for materials from SPS to Netsuite | L41: 1418.87
B42: Journal | C42: 45845 | D42: JE1020 | F42: Auburn Hospitality Group | G42: F | H42: A12001 - Inventory (GV LLC) (New) : Inventory (New) | I42: 38403/2 | J42: Auburn Hospitality GroupImport July 25 cogs for materials from SPS to Netsuite | K42: Auburn Hospitality GroupImport July 25 cogs for materials from SPS to Netsuite | L42: 570.62
B43: Journal | C43: 45845 | D43: JE1022 | F43: Auburn Hospitality Group | G43: F | H43: A12001 - Inventory (GV LLC) (New) : Inventory (New) | I43: 38403/4 | J43: Auburn Hospitality GroupImport July 25 cogs for materials from SPS to Netsuite | K43: Auburn Hospitality GroupImport July 25 cogs for materials from SPS to Netsuite | L43: 3038.69
B44: Journal | C44: 45845 | D44: JE1013 | F44: Fairfield Townplace East Hartford | G44: F | H44: A12001 - Inventory (GV LLC) (New) : Inventory (New) | I44: 35796/2 | J44: Fairfield Townplace East HartfordImport July 25 cogs for materials from SPS to Netsuite | K44: Fairfield Townplace East HartfordImport July 25 cogs for materials from SPS to Netsuite | L44: 5111.26
B45: Journal | C45: 45846 | D45: JE1024 | F45: Auburn Hospitality Group | G45: F | H45: A12001 - Inventory (GV LLC) (New) : Inventory (New) | I45: 38394/3 | J45: Auburn Hospitality GroupImport July 25 cogs for materials from SPS to Netsuite | K45: Auburn Hospitality GroupImport July 25 cogs for materials from SPS to Netsuite | L45: 6013.29
...

Sheet tab 5 Nsuite Aug income statemn
A1: Graniti Vicentia, L.L.C.
A2: Parent Company : Graniti Vicentia LLC
A3: Graniti - Income Statement Detail
A4: Aug 2025
A6: Options: Activity Only
A7: Financial Row | B7: Type | C7: Date | D7: Document Number | E7: Name | F7: Entity (Line) | G7: Clr | H7: Split | I7: Reference No. | J7: Description | K7: Memo | L7: Amount
A8: Ordinary Income/Expense
A9: Cost Of Sales
A10: A50000 - Cost of Goods Sales 50 (GV LLC) (New)
A11: A50001 - Cost Of Goods Sold (New)
B12: Bill | C12: 45870 | D12: BILL_30207 | E12: MirageGranitoCeramico S.p.A | F12: - No Entity - | G12: F | H12: A20001 - Accounts Payable (GV LLC) (New) : Accounts Payable Suppliers & Vendors (New) | J12: Cost of Sales Adjustment | K12: 266/VE - Import SPS data by Invoice in NetSuite | L12: 371.07 | N12: 0
B13: Bill | C13: 45870 | D13: BILL_30208 | E13: MirageGranitoCeramico S.p.A | F13: - No Entity - | G13: F | H13: A20001 - Accounts Payable (GV LLC) (New) : Accounts Payable Suppliers & Vendors (New) | J13: Cost of Sales Adjustment | K13: 266/VE - Import SPS data by Invoice in NetSuite | L13: 6649.38 | N13: Type
B14: Bill | C14: 45870 | D14: BILL_30206 | E14: MirageGranitoCeramico S.p.A | F14: - No Entity - | G14: F | H14: A20001 - Accounts Payable (GV LLC) (New) : Accounts Payable Suppliers & Vendors (New) | J14: Cost of Sales Adjustment | K14: 266/VE - Import SPS data by Invoice in NetSuite | L14: 6350.4 | N14: Bill | O14: =SUMIF(B:B,N14,L:L) -> 30883.73
B15: Bill | C15: 45870 | D15: BILL_30205 | E15: MirageGranitoCeramico S.p.A | F15: - No Entity - | G15: F | H15: A20001 - Accounts Payable (GV LLC) (New) : Accounts Payable Suppliers & Vendors (New) | J15: Cost of Sales Adjustment | K15: 266/VE - Import SPS data by Invoice in NetSuite | L15: 346.32 | N15: Bill Credit | O15: =SUMIF(B:B,N15,L:L) -> -997.93
B16: Bill Credit | C16: 45870 | D16: Credit-1 | E16: MirageGranitoCeramico S.p.A | F16: - No Entity - | G16: F | H16: 20000 - Accounts Payable | J16: apply this one to PO42868 | L16: -924.6 | N16: Journal | O16: =SUMIF(B:B,N16,L:L) -> 6878885.8
B17: Bill Credit | C17: 45870 | D17: Credit-2 | E17: MirageGranitoCeramico S.p.A | F17: - No Entity - | G17: F | H17: 20000 - Accounts Payable | L17: -73.33 | N17: Item Fulfillment | O17: =SUMIF(B:B,N17,L:L) -> 13764.53
B18: Journal | C18: 45870 | D18: JE1844 | F18: Ascent Residence inn Montgomery | G18: F | H18: A12001 - Inventory (GV LLC) (New) : Inventory (New) | I18: 37684/3 | J18: Ascent Residence inn Montgomery - Aug material cost transferred from sps | K18: Ascent Residence inn Montgomery - Aug material cost transferred from sps | L18: 45093.1 | N18: Item Receipt | O18: =SUMIF(B:B,N18,L:L) -> 21613.28
B19: Journal | C19: 45870 | D19: JE1845 | F19: MDC Interior Solutions | G19: F | H19: A12001 - Inventory (GV LLC) (New) : Inventory (New) | I19: 41188101 | J19: MDC Interior Solutions - Aug material cost transferred from sps | K19: MDC Interior Solutions - Aug material cost transferred from sps | L19: 113.4
B20: Item Fulfillment | C20: 45873 | D20: IF367 | E20: Ascent Hospitality Management Co | F20: Ascent Hospitality Management Co | G20: F | H20: A12001 - Inventory (GV LLC) (New) : Inventory (New) | J20: Cost of Sales | L20: 3703.47
B21: Journal | C21: 45873 | D21: JE1846 | F21: Fairfield Townplace East Hartford | G21: F | H21: A12001 - Inventory (GV LLC) (New) : Inventory (New) | I21: 35804/4 | J21: Fairfield Townplace East Hartford - Aug material cost transferred from sps | K21: Fairfield Townplace East Hartford - Aug material cost transferred from sps | L21: 21564.59
B22: Journal | C22: 45873 | D22: JE1847 | F22: Classic American Homes & Renovations | G22: F | H22: A12001 - Inventory (GV LLC) (New) : Inventory (New) | I22: 38633 | J22: Classic American Homes & Renovations - Aug material cost transferred from sps | K22: Classic American Homes & Renovations - Aug material cost transferred from sps | L22: 996.55
B23: Bill | C23: 45874 | D23: 19542/VE | E23: MirageGranitoCeramico S.p.A | F23: - No Entity - | G23: F | H23: A20001 - Accounts Payable (GV LLC) (New) : Accounts Payable Suppliers & Vendors (New) | J23: Cost of Sales Adjustment | K23: Import SPS data by Invoice in NetSuite | L23: 2116.8
B24: Journal | C24: 45874 | D24: JE1849 | F24: Chesterfield Hospitality, Inc. | G24: F | H24: A12001 - Inventory (GV LLC) (New) : Inventory (New) | I24: 38299/3 | J24: Chesterfield Hospitality, Inc. - Aug material cost transferred from sps | K24: Chesterfield Hospitality, Inc. - Aug material cost transferred from sps | L24: 11730.06
B25: Journal | C25: 45874 | D25: JE1850 | F25: Chesterfield Hospitality, Inc. | G25: F | H25: A12001 - Inventory (GV LLC) (New) : Inventory (New) | I25: 38301/4 | J25: Chesterfield Hospitality, Inc. - Aug material cost transferred from sps | K25: Chesterfield Hospitality, Inc. - Aug material cost transferred from sps | L25: 7314.78
B26: Journal | C26: 45874 | D26: JE1848 | F26: Hampton Inn Nashville | G26: F | H26: A12001 - Inventory (GV LLC) (New) : Inventory (New) | I26: 38235/6 | J26: Hampton Inn Nashville - Aug material cost transferred from sps | K26: Hampton Inn Nashville - Aug material cost transferred from sps | L26: 14077.81
B27: Journal | C27: 45874 | D27: JE1851 | F27: Chesterfield Hospitality, Inc. | G27: F | H27: A12001 - Inventory (GV LLC) (New) : Inventory (New) | I27: 38304/3 | J27: Chesterfield Hospitality, Inc. - Aug material cost transferred from sps | K27: Chesterfield Hospitality, Inc. - Aug material cost transferred from sps | L27: 1256.79
B28: Item Fulfillment | C28: 45875 | D28: IF279 | E28: Umang patel | F28: Umang patel | G28: F | H28: A12001 - Inventory (GV LLC) (New) : Inventory (New) | J28: Cost of Sales | L28: 3965.73
B29: Item Fulfillment | C29: 45876 | D29: IF280 | E29: SKIMS Retail | F29: SKIMS Retail | G29: F | H29: A12001 - Inventory (GV LLC) (New) : Inventory (New) | J29: Cost of Sales | L29: 6095.33
B30: Journal | C30: 45876 | D30: JE1853 | F30: Ascent Residence inn Montgomery | G30: F | H30: A12001 - Inventory (GV LLC) (New) : Inventory (New) | I30: 37697/3 | J30: Ascent Residence inn Montgomery - Aug material cost transferred from sps | K30: Ascent Residence inn Montgomery - Aug material cost transferred from sps | L30: 708.57
B31: Journal | C31: 45876 | D31: JE1854 | F31: Comfort Suites NC330 | G31: F | H31: A12001 - Inventory (GV LLC) (New) : Inventory (New) | I31: 38661 | J31: Comfort suites NC330 - Aug material cost transferred from sps | K31: Comfort suites NC330 - Aug material cost transferred from sps | L31: 2966.73
B32: Journal | C32: 45876 | D32: JE1852 | F32: Ascent Residence inn Montgomery | G32: F | H32: A12001 - Inventory (GV LLC) (New) : Inventory (New) | I32: 37687 | J32: Ascent Residence inn Montgomery - Aug material cost transferred from sps | K32: Ascent Residence inn Montgomery - Aug material cost transferred from sps | L32: 222.07
B33: Journal | C33: 45877 | D33: JE1855 | F33: Kings Bay Coastal Hotel Management LLC / Wingate Kingsland | G33: F | H33: A12001 - Inventory (GV LLC) (New) : Inventory (New) | I33: 36248 | J33: Kings Bay Coastal Hotel Management LLC / Wingate Kingsland - Aug material cost transferred from sps | K33: Kings Bay Coastal Hotel Management LLC / Wingate Kingsland - Aug material cost transferred from sps | L33: 20
B34: Journal | C34: 45877 | D34: JE1858 | F34: Veranda Homes | G34: F | H34: A12001 - Inventory (GV LLC) (New) : Inventory (New) | I34: 38292 | J34: Veranda Homes - Aug material cost transferred from sps | K34: Veranda Homes - Aug material cost transferred from sps | L34: 24766.76
B35: Journal | C35: 45877 | D35: JE1857 | F35: Ascent Hospitality Element Carmel Indiana | G35: F | H35: A12001 - Inventory (GV LLC) (New) : Inventory (New) | I35: 37412/2 | J35: Ascent Hospitality Element Carmel Indiana - Aug material cost transferred from sps | K35: Ascent Hospitality Element Carmel Indiana - Aug material cost transferred from sps | L35: 708.08
B36: Journal | C36: 45877 | D36: JE1859 | F36: Veranda Homes | G36: F | H36: A12001 - Inventory (GV LLC) (New) : Inventory (New) | I36: 38292/2 | J36: Veranda Homes - Aug material cost transferred from sps | K36: Veranda Homes - Aug material cost transferred from sps | L36: 9768.7
B37: Journal | C37: 45877 | D37: JE1856 | F37: Kings Bay Coastal Hotel Management LLC / Wingate Kingsland | G37: F | H37: A12001 - Inventory (GV LLC) (New) : Inventory (New) | I37: 36250 | J37: Kings Bay Coastal Hotel Management LLC / Wingate Kingsland - Aug material cost transferred from sps | K37: Kings Bay Coastal Hotel Management LLC / Wingate Kingsland - Aug material cost transferred from sps | L37: 7206.63
B38: Journal | C38: 45880 | D38: JE3155 | F38: HOME2 SOMERSET | G38: F | H38: A12001 - Inventory (GV LLC) (New) : Inventory (New) | I38: 38260 | J38: HOME2 SOMERSET - Aug material cost transferred from sps | K38: HOME2 SOMERSET - Aug material cost transferred from sps | L38: 6467.32
B39: Journal | C39: 45880 | D39: JE1861 | F39: Mesquite Gaming | G39: F | H39: A12001 - Inventory (GV LLC) (New) : Inventory (New) | I39: 38579 | J39: Mesquite Gaming - Aug material cost transferred from sps | K39: Mesquite Gaming - Aug material cost transferred from sps | L39: 990.31
B40: Journal | C40: 45880 | D40: JE3154 | F40: HOME2 SOMERSET | G40: F | H40: A12001 - Inventory (GV LLC) (New) : Inventory (New) | I40: 38259 | J40: HOME2 SOMERSET - Aug material cost transferred from sps | K40: HOME2 SOMERSET - Aug material cost transferred from sps | L40: 365.65
B41: Journal | C41: 45880 | D41: JE1860 | F41: Ascent Hospitality Tribute Carmel Indiana | G41: F | H41: A12001 - Inventory (GV LLC) (New) : Inventory (New) | I41: 36663/2 | J41: Ascent Hospitality Tribute Carmel Indiana - Aug material cost transferred from sps | K41: Ascent Hospitality Tribute Carmel Indiana - Aug material cost transferred from sps | L41: 566.78
...

Sheet tab 6 Nsuite Jul Bs Inventory
A1: Graniti Vicentia, L.L.C.
A2: Parent Company : Graniti Vicentia LLC
A3: Balance Sheet Detail
A4: Jul 2025
A7: Financial Row | B7: Type | C7: Date | D7: Document Number | E7: Name | F7: Amount | G7: Balance
A8: ASSETS | F8: 0 | G8: 0
A9: Current Assets | F9: 0 | G9: 0
A10: Other Current Asset | F10: 0 | G10: 0
A11: A12000 - Inventory (GV LLC) (New) | F11: 0 | G11: 0
A12: A12001 - Inventory (New) | F12: 0 | G12: 14946309 | I12: {=_xlfn.UNIQUE(B:B)} -> 0
B13: Journal | C13: 45839 | D13: JE995 | E13: Magnolia LXR Dallas TX - | F13: -78.61 | G13: =G12+F13 -> 14946230 | I13: Type
B14: Journal | C14: 45839 | D14: JE998 | E14: Magnolia LXR Dallas TX - | F14: -3554.96 | G14: =G13+F14 -> 14942675 | I14: Journal | J14: =SUMIF(B:B,I14,F:F) -> -1944660.1
B15: Journal | C15: 45839 | D15: JE999 | E15: La Quinta Orlando | F15: -893.18 | G15: =G14+F15 -> 14941782 | I15: Item Receipt | J15: =SUMIF(B:B,I15,F:F) -> 582955.58
B16: Journal | C16: 45839 | D16: JE1000 | E16: LaQuinta/Hawthone - Knoxville TN - AMit | F16: -848 | G16: =G15+F16 -> 14940934 | I16: Bill | J16: =SUMIF(B:B,I16,F:F) -> 16120.06
B17: Journal | C17: 45839 | D17: JE1001 | E17: Magnolia LXR Dallas TX - | F17: -10311.03 | G17: =G16+F17 -> 14930623
B18: Journal | C18: 45839 | D18: JE1002 | E18: La Quinta, Anaheim CA | F18: -980.95 | G18: =G17+F18 -> 14929642
B19: Journal | C19: 45839 | D19: JE1003 | E19: LaQuinta Yakima WA | F19: -541.7 | G19: =G18+F19 -> 14929101
B20: Journal | C20: 45839 | D20: JE1004 | E20: LaQuinta Inn & Suites Oxford AL | F20: -3300.55 | G20: =G19+F20 -> 14925800
B21: Journal | C21: 45839 | D21: JE1005 | E21: Hampton Downtown Montgomery | F21: -28372.9 | G21: =G20+F21 -> 14897427
B22: Journal | C22: 45839 | D22: JE1006 | E22: Graniti Vicentia | F22: -1277.06 | G22: =G21+F22 -> 14896150
B23: Journal | C23: 45839 | D23: JE1007 | E23: Graniti Vicentia | F23: -2609.63 | G23: =G22+F23 -> 14893540
B24: Journal | C24: 45839 | D24: JE1008 | E24: CANDLEWOOD EASTRIDGE TN | F24: -386.87 | G24: =G23+F24 -> 14893154
B25: Journal | C25: 45839 | D25: JE1009 | E25: Fairfield Townplace East Hartford | F25: -23478.33 | G25: =G24+F25 -> 14869675
B26: Journal | C26: 45839 | D26: JE1010 | E26: ELEMENT FORTSMITH, ARKANSAS | F26: -8127.55 | G26: =G25+F26 -> 14861548
B27: Journal | C27: 45839 | D27: JE1011 | E27: Monsoon Flower LLC | F27: -12463.65 | G27: =G26+F27 -> 14849084
B28: Journal | C28: 45839 | D28: JE1012 | E28: Pitt-Cran Hospitality, LLC/ Wingate Cranberry | F28: -787.36 | G28: =G27+F28 -> 14848297
... B42: Item Receipt | C42: 45843 | D42: IR912 | E42: Jasfer Industry Co., Limited | F42: 261.99 | G42: =G41+F42 -> 14840195
B43: Bill | C43: 45845 | D43: 60174 - MSKU1005018 - 20250717 | F43: 12814 | G43: =G42+F43 -> 14853009
B44: Bill | C44: 45845 | D44: 60174 - MSKU1005018 - 20250717 | F44: 461.5 | G44: =G43+F44 -> 14853471
B45: Item Receipt | C45: 45845 | D45: IR914 | E45: Modular Shower Walls | F45: 9925.2 | G45: =G44+F45 -> 14863396
B46: Item Receipt | C46: 45845 | D46: IR914 | E46: Modular Shower Walls | F46: 10476.6 | G46: =G45+F46 -> 14873873
B47: Item Receipt | C47: 45845 | D47: IR914 | E47: Modular Shower Walls | F47: 530.2 | G47: =G46+F47 -> 14874403
B48: Item Receipt | C48: 45845 | D48: IR915 | E48: Modular Shower Walls | F48: 4995.9 | G48: =G47+F48 -> 14879399
B49: Item Receipt | C49: 45845 | D49: IR915 | E49: Modular Shower Walls | F49: 6185.4 | G49: =G48+F49 -> 14885584
B50: Item Receipt | C50: 45845 | D50: IR915 | E50: Modular Shower Walls | F50: 488.2 | G50: =G49+F50 -> 14886072
B51: Item Receipt | C51: 45845 | D51: IR915 | E51: Modular Shower Walls | F51: 696 | G51: =G50+F51 -> 14886768
B52: Item Receipt | C52: 45845 | D52: IR915 | E52: Modular Shower Walls | F52: 658 | G52: =G51+F52 -> 14887426
B53: Item Receipt | C53: 45845 | D53: IR916 | E53: Easy Stones | F53: 1275 | G53: =G52+F53 -> 14888701
B54: Item Receipt | C54: 45845 | D54: IR917 | E54: Modular Shower Walls | F54: 542.88 | G54: =G53+F54 -> 14889244
B55: Item Receipt | C55: 45845 | D55: IR918 | E55: Kronos USA | F55: 18135 | G55: =G54+F55 -> 14907379
...

Sheet tab 7 nsuite aug bs inventry
A1: Graniti Vicentia, L.L.C.
A2: Parent Company : Graniti Vicentia LLC
A3: Balance Sheet Detail
A4: Aug 2025
A7: Financial Row | B7: Type | C7: Date | D7: Document Number | E7: Name | F7: Amount | G7: Balance | I7: 0
A8: ASSETS | F8: 0 | G8: 0 | I8: Type
A9: Current Assets | F9: 0 | G9: 0 | I9: Bill | J9: =SUMIF(B:B,I9,F:F) -> 485
A10: Other Current Asset | F10: 0 | G10: 0 | I10: Inventory Adjustment | J10: =SUMIF(B:B,I10,F:F) -> 3703.47
A11: A12000 - Inventory (GV LLC) (New) | F11: 0 | G11: 0 | I11: Journal | J11: =SUMIF(B:B,I11,F:F) -> -6830880.6
A12: A12001 - Inventory (New) | F12: 0 | G12: 13600724 | I12: Item Fulfillment | J12: =SUMIF(B:B,I12,F:F) -> -13764.53
B13: Bill | C13: 45870 | D13: BILL_30205 | F13: 346.32 | G13: =G12+F13 -> 13601071 | I13: Item Receipt | J13: =SUMIF(B:B,I13,F:F) -> 367472.18
B14: Bill | C14: 45870 | D14: BILL_30205 | F14: -346.32 | G14: =G13+F14 -> 13600724
B15: Bill | C15: 45870 | D15: BILL_30206 | F15: 6350.4 | G15: =G14+F15 -> 13607075 | J15: =SUM(J9:J13) -> -6472984.5
B16: Bill | C16: 45870 | D16: BILL_30206 | F16: -6350.4 | G16: =G15+F16 -> 13600724
B17: Bill | C17: 45870 | D17: BILL_30207 | F17: 371.07 | G17: =G16+F17 -> 13601096
B18: Bill | C18: 45870 | D18: BILL_30207 | F18: -371.07 | G18: =G17+F18 -> 13600724
B19: Bill | C19: 45870 | D19: BILL_30208 | F19: 6649.38 | G19: =G18+F19 -> 13607374
B20: Bill | C20: 45870 | D20: BILL_30208 | F20: -6649.38 | G20: =G19+F20 -> 13600724
B21: Inventory Adjustment | C21: 45870 | D21: IA350 | F21: 3703.47 | G21: =G20+F21 -> 13604428
B22: Journal | C22: 45870 | D22: JE1844 | E22: Ascent Residence inn Montgomery | F22: -45093.1 | G22: =G21+F22 -> 13559335
B23: Journal | C23: 45870 | D23: JE1845 | E23: MDC Interior Solutions | F23: -113.4 | G23: =G22+F23 -> 13559221
B24: Item Fulfillment | C24: 45873 | D24: IF367 | E24: Ascent Hospitality Management Co | F24: -3703.47 | G24: =G23+F24 -> 13555518
B25: Item Receipt | C25: 45873 | D25: IR607 | E25: WOW USA, Inc. | F25: 497 | G25: =G24+F25 -> 13556015
B26: Item Receipt | C26: 45873 | D26: IR610 | E26: MS International, Inc. | F26: 481.14 | G26: =G25+F26 -> 13556496
B27: Item Receipt | C27: 45873 | D27: IR610 | E27: MS International, Inc. | F27: 199.2 | G27: =G26+F27 -> 13556695
B28: Journal | C28: 45873 | D28: JE1846 | E28: Fairfield Townplace East Hartford | F28: -21564.59 | G28: =G27+F28 -> 13535131
B29: Journal | C29: 45873 | D29: JE1847 | E29: Classic American Homes & Renovations | F29: -996.55 | G29: =G28+F29 -> 13534134
B30: Bill | C30: 45874 | D30: 19542/VE | F30: 2116.8 | G30: =G29+F30 -> 13536251
B31: Bill | C31: 45874 | D31: 19542/VE | F31: -2116.8 | G31: =G30+F31 -> 13534134
B32: Journal | C32: 45874 | D32: JE1848 | E32: Hampton Inn Nashville | F32: -14077.81 | G32: =G31+F32 -> 13520056
B33: Journal | C33: 45874 | D33: JE1849 | E33: Chesterfield Hospitality, Inc. | F33: -11730.06 | G33: =G32+F33 -> 13508326
B34: Journal | C34: 45874 | D34: JE1850 | E34: Chesterfield Hospitality, Inc. | F34: -7314.78 | G34: =G33+F34 -> 13501012
B35: Journal | C35: 45874 | D35: JE1851 | E35: Chesterfield Hospitality, Inc. | F35: -1256.79 | G35: =G34+F35 -> 13499755
B36: Item Fulfillment | C36: 45875 | D36: IF279 | E36: Umang patel | F36: -3965.73 | G36: =G35+F36 -> 13495789
B37: Item Receipt | C37: 45875 | D37: IR654 | E37: Jasfer Industry Co., Limited | F37: 21750.87 | G37: =G36+F37 -> 13517540
B38: Item Receipt | C38: 45875 | D38: IR654 | E38: Jasfer Industry Co., Limited | F38: 1409.54 | G38: =G37+F38 -> 13518949
B39: Item Receipt | C39: 45875 | D39: IR654 | E39: Jasfer Industry Co., Limited | F39: 24042.13 | G39: =G38+F39 -> 13542992
B40: Item Receipt | C40: 45875 | D40: IR654 | E40: Jasfer Industry Co., Limited | F40: 15228.78 | G40: =G39+F40 -> 13558220
B41: Item Receipt | C41: 45875 | D41: IR654 | E41: Jasfer Industry Co., Limited | F41: 750.04 | G41: =G40+F41 -> 13558970
B42: Item Receipt | C42: 45875 | D42: IR654 | E42: Jasfer Industry Co., Limited | F42: 2351.95 | G42: =G41+F42 -> 13561322
...

Sheet tab 11 SpS comparative 
A1: Balance Sheet Comparison: Monthly
A2: All Locations
B3: 45748 | D3: 45778 | F3: 45809 | H3: 45839 | J3: 45870 | L3: 45901 | N3: 45931 | P3: 45962 | R3: 45992 | T3: 46023 | V3: 46054 | X3: 46082
A4: ASSETS
A5: Current Assets
A6: 10002 - Truist -Savings -4645 | B6: 1311.53 | D6: 1311.53 | F6: 1311.53 | H6: 1311.53 | J6: 1311.53 | L6: 1311.53 | N6: 1311.53 | P6: 1311.53 | R6: 1311.53 | T6: 1311.53 | V6: 1311.53 | X6: 1311.53
A7: 10003 - Allegiance Bank Texas-2243 | B7: 39327.11 | D7: 50582.4 | F7: 936.03 | H7: 936.03 | J7: 936.03 | L7: 616.03 | N7: 616.03 | P7: 616.03 | R7: 616.03 | T7: 616.03 | V7: 616.03 | X7: 616.03
A8: 10008 - Truist Bank - 4637 | B8: -4673.75 | D8: 20762.76 | F8: 8099.13 | H8: 8099.13 | J8: 8099.13 | L8: 2437119.5 | N8: 2437119.5 | P8: 2437119.5 | R8: 2437119.5 | T8: 2437119.5 | V8: 2437119.5 | X8: 2437119.5
A9: 10010 - Petty Cash On Hand | B9: 2063.36 | D9: 2063.36 | F9: 2063.36 | H9: 2063.36 | J9: 2063.36 | L9: -7238.14 | N9: -7238.14 | P9: -7238.14 | R9: -7238.14 | T9: -7238.14 | V9: -7238.14 | X9: -7238.14
A10: 10017 - Prepayment to Suppliers | B10: 5225.47 | D10: 5226.45 | F10: 38259.34 | H10: 38259.34 | J10: 38259.34 | L10: 38259.34 | N10: 38259.34 | P10: 38259.34 | R10: 38259.34 | T10: 38259.34 | V10: 38259.34 | X10: 38259.34
A11: 10019 - CC-Clearing Account | B11: -1993.65 | D11: -2633.85 | F11: -4091.4 | H11: -4091.4 | J11: -4091.4 | L11: -4091.4 | N11: -4091.4 | P11: -4091.4 | R11: -4091.4 | T11: -4091.4 | V11: -4091.4 | X11: -4091.4
A12: 11000 - Accounts Receivable | B12: 10320476 | D12: 9213673.8 | F12: 13450222 | H12: 15765431 | J12: 16292262 | L12: 17023453 | N12: 17023453 | P12: 17023453 | R12: 17023453 | T12: 17023453 | V12: 17023453 | X12: 17023453
A13: 11000.01 - Allowance for Doubtful Accounts | B13: -766001.85 | D13: -766001.85 | F13: -766001.85 | H13: -766001.85 | J13: -766001.85 | L13: -766001.85 | N13: -766001.85 | P13: -766001.85 | R13: -766001.85 | T13: -766001.85 | V13: -766001.85 | X13: -766001.85
A14: Total Current Assets | B14: 9595734 | D14: 8524984.6 | F14: 12730798 | H14: 15046008 | J14: 15572838 | L14: 18723428 | N14: 18723428 | P14: 18723428 | R14: 18723428 | T14: 18723428 | V14: 18723428 | X14: 18723428
A15: Fixed Assets
A16: 14000 - Automobile | B16: 437491.46 | D16: 437491.46 | F16: 437491.46 | H16: 437491.46 | J16: 437491.46 | L16: 437491.46 | N16: 437491.46 | P16: 437491.46 | R16: 437491.46 | T16: 437491.46 | V16: 437491.46 | X16: 437491.46
A17: 14100 - Furniture & Fixture | B17: 41183.31 | D17: 41183.31 | F17: 41183.31 | H17: 41183.31 | J17: 41183.31 | L17: 41183.31 | N17: 41183.31 | P17: 41183.31 | R17: 41183.31 | T17: 41183.31 | V17: 41183.31 | X17: 41183.31
A18: 14150 - Computer & Electronics | B18: 449068.68 | D18: 449068.68 | F18: 449068.68 | H18: 449068.68 | J18: 449068.68 | L18: 449068.68 | N18: 449068.68 | P18: 449068.68 | R18: 449068.68 | T18: 449068.68 | V18: 449068.68 | X18: 449068.68
A19: 14200 - Machinery & Equipment | B19: 2120560.2 | D19: 2120560.2 | F19: 2120560.2 | H19: 2120560.2 | J19: 2120560.2 | L19: 2120560.2 | N19: 2120560.2 | P19: 2120560.2 | R19: 2120560.2 | T19: 2120560.2 | V19: 2120560.2 | X19: 2120560.2
A20: 14300 - Leasehold Improvements | B20: 4413527.2 | D20: 4413527.2 | F20: 5633130.9 | H20: 5633130.9 | J20: 5633130.9 | L20: 5633130.9 | N20: 5633130.9 | P20: 5633130.9 | R20: 5633130.9 | T20: 5633130.9 | V20: 5633130.9 | X20: 5633130.9
A21: 14600 - Construction in Process | B21: 1500 | D21: 4802 | F21: 4802 | H21: 4802 | J21: 4802 | L21: 4802 | N21: 4802 | P21: 4802 | R21: 4802 | T21: 4802 | V21: 4802 | X21: 4802
A22: 14500 - Accumulated Depreciation | B22: -2794367.4 | D22: -2839202.7 | F22: -2884036.8 | H22: -2973211.9 | J22: -3062453.6 | L22: -3137996.9 | N22: -3137996.9 | P22: -3093656 | R22: -3004974 | T22: -3004974 | V22: -3004974 | X22: -3004974
A23: Total Fixed Assets | B23: 4668963.5 | D23: 4627430.2 | F23: 5802199.8 | H23: 5713024.7 | J23: 5623782.9 | L23: 5548239.7 | N23: 5548239.7 | P23: 5592580.6 | R23: 5681262.5 | T23: 5681262.5 | V23: 5681262.5 | X23: 5681262.5
A24: Other Current Assets
A25: 11050 - Accrued Accounts Receivable | B25: 11870 | D25: 11150 | F25: 15430 | H25: 15430 | J25: 15430 | L25: 15430 | N25: 15430 | P25: 15430 | R25: 15430 | T25: 15430 | V25: 15430 | X25: 15430
A26: 12000 - Inventory | B26: 19713436 | D26: 20197448 | F26: 14933430 | H26: 15686330 | J26: 11836929 | L26: 14171144 | N26: 14171144 | P26: 14171144 | R26: 14171144 | T26: 14171144 | V26: 14171144 | X26: 14171144
A27: 12050 - Inventory Allowances | B27: -1000000 | D27: -1000000 | F27: -1000000 | H27: -1000000 | J27: -1000000 | L27: -1000000 | N27: -1000000 | P27: -1000000 | R27: -1000000 | T27: -1000000 | V27: -1000000 | X27: -1000000
